Workbook

Sheet Read Me
A1: Purpose | B1: One hierarchy that every MDP geographic label points to. Fix a place once on Hierarchy and every label that maps to it follows.
A3: HIERARCHY LEVELS
A4: Global | B4: Root. Also holds non-regional buckets (International, Domestic, Rest of World, Other) and multi-region composites
A5: Region | B5: AMER (Americas) · EMEA (Europe, Middle East, and Africa) · APAC (Asia-Pacific)
A6: Sub-region | B6: AMER: North America (NORAM), Latin America (LATAM) · EMEA: Europe, Middle East, Africa · APAC: South Asia, East Asia, Southeast Asia (ASEAN), Oceania (ANZ)
A7: Country | B7: All 242 inhabited ISO 3166 countries/territories plus Kosovo, with ISO3. Groupings column shows memberships (Western Europe, EU, Nordics, GCC, Greater China…)
A8: State/Province | B8: US, Canada, Mexico, Brazil, UK, Germany, France, UAE, Saudi Arabia, South Africa, Nigeria, India, China, Japan, Indonesia, Malaysia, Australia, New Zealand. US regions (incl. Census divisions) and cities also sit under their country
A9: EMEA sub-regions | B9: Europe · Middle East · Africa (components: North Africa, Sub-Saharan Africa and its West/East/Central/Southern Africa). MENA = Middle East + North Africa, kept as a grouping
A10: Components | B10: Sit inside one sub-region: e.g. Western Europe, CEE, Nordics, DACH under Europe; Middle East, North Africa, GCC under MENA; Greater China, Northeast Asia under East Asia; Caribbean, Central/South America under LATAM
A11: Tree View | B11: Indented view of Global > Region > Sub-region > Country > State/Province (and business regions) > City, in the same order as Hierarchy
A12: Business groupings | B12: NOLA, SOLA, CAC, NAFTA/USMCA, Mercosur, Pacific Alliance, CEEMEA, Northern/Central/Southeast Europe, Scandinavia, Maghreb, West/East/Central/Southern Africa, Mekong; market groupings BRIC, BRICS, G7, OECD, Frontier
A13: Cities | B13: ~200 major business cities and metro areas (Greater Toronto Area, Bay Area, Dallas–Fort Worth…) placed under state/province where known
A15: MAPPING RULES
A16: 1. Smallest container | B16: Map each label to the smallest node that fully contains what it describes (China + Hong Kong → Greater China)
A17: 2. Scope | B17: Exact = same geography · Partial = subset, e.g. 'Europe excl. UK' · Residual = 'Other X' · Combined = spans several nodes under one parent
A18: 3. International | B18: When a filing gives only broad non-US reporting (Foreign, Non-US, Outside the U.S.), use International
A19: 4. Cross-region | B19: Labels spanning regions go to a Multi-region node, never to one of the regions they span
A20: 5. Not a place | B20: Segments, facilities, tax categories and scraper artifacts go on Excluded
A22: HOW TO MAINTAIN
A23: New label | B23: Paste it into New Label Check. If Auto-matched, add it to Label Map with that node. If UNMAPPED, add a Label Map row and pick a node from the dropdown in column D
A24: New place | B24: Add one row on Hierarchy only when no existing node fits
A25: Reclassify | B25: Change Region/Sub-region on the node's Hierarchy row; all mapped labels update
A26: Blue text | B26: Inputs you edit. Black text is formula-driven
A28: COUNTS
A29: Hierarchy nodes | B29: =COUNTA(Hierarchy!A2:A1295) -> 1294
A30: Labels mapped | B30: =COUNTA('Label Map'!A2:A2019) -> 2018
A31: Labels pre-seeded for future scrapes | B31: =COUNTIF('Label Map'!M2:M2019,"Pre-seeded") -> 1341
A32: Labels changed vs previous | B32: =COUNTIF('Label Map'!M2:M2019,"Changed") -> 240
A33: Labels excluded | B33: =COUNTA(Excluded!A2:A19) -> 18
A34: Key conflicts (should be 0) | B34: =COUNTIF('Label Map'!O2:O2019,"CONFLICT") -> 0
A35: Node not found (should be 0) | B35: =COUNTIF('Label Map'!F2:F2019,"NODE NOT FOUND") -> 0
A36: Open decisions | B36: See Decisions sheet
A38: SOURCES
A39: UN M49 | B39: UN Statistics Division M49 standard (region, sub-region, intermediate region, LDC/LLDC/SIDS) via the datasets/country-codes open dataset: github.com/datasets/country-codes
A40: World Bank | B40: World Bank Country and Lending Groups, FY27 (thresholds on 2025 GNI per capita, Atlas method): datahelpdesk.worldbank.org/knowledgebase/articles/906519
A41: States/provinces | B41: ISO 3166-2 subdivisions (English names used; local spellings pre-seeded as aliases)

Sheet Hierarchy
A1: Standard Node | B1: Level | C1: Global | D1: Region | E1: Sub-region | F1: Country | G1: ISO3 | H1: State/Province | I1: City | J1: Parent Node | K1: Groupings | L1: UN M49 Region | M1: UN M49 Sub-region | N1: UN M49 Intermediate Region | O1: World Bank Region (FY27) | P1: World Bank Income Group (FY27) | Q1: Definition / Notes | R1: Labels Mapped
A2: Global | B2: Global | C2: Global | D2: Global | Q2: Root of the hierarchy — worldwide / consolidated total | R2: =COUNTIF('Label Map'!$D$2:$D$2000,A2) -> 3
A3: AMER (Americas) | B3: Region | C3: Global | D3: AMER | J3: Global | Q3: North America (NORAM) + Latin America (LATAM) | R3: =COUNTIF('Label Map'!$D$2:$D$2000,A3) -> 22
A4: NAFTA / USMCA | B4: Sub-region group | C4: Global | D4: AMER | J4: AMER (Americas) | Q4: Members: United States, Canada, Mexico — spans NORAM and LATAM | R4: =COUNTIF('Label Map'!$D$2:$D$2000,A4) -> 4
A5: North America (NORAM) | B5: Sub-region | C5: Global | D5: AMER | E5: North America (NORAM) | J5: AMER (Americas) | R5: =COUNTIF('Label Map'!$D$2:$D$2000,A5) -> 15
A6: United States | B6: Country | C6: Global | D6: AMER | E6: North America (NORAM) | F6: United States | G6: USA | J6: North America (NORAM) | K6: NAFTA / USMCA, G7, OECD | L6: Americas | M6: Northern America | O6: North America | P6: High income | R6: =COUNTIF('Label Map'!$D$2:$D$2000,A6) -> 42
A7: US Carolinas | B7: Sub-national region | C7: Global | D7: AMER | E7: North America (NORAM) | F7: United States | G7: USA | J7: United States | Q7: North and South Carolina | R7: =COUNTIF('Label Map'!$D$2:$D$2000,A7) -> 1
A8: US Central | B8: Sub-national region | C8: Global | D8: AMER | E8: North America (NORAM) | F8: United States | G8: USA | J8: United States | R8: =COUNTIF('Label Map'!$D$2:$D$2000,A8) -> 3
A9: US East | B9: Sub-national region | C9: Global | D9: AMER | E9: North America (NORAM) | F9: United States | G9: USA | J9: United States | R9: =COUNTIF('Label Map'!$D$2:$D$2000,A9) -> 3
A10: US East North Central | B10: Sub-national region | C10: Global | D10: AMER | E10: North America (NORAM) | F10: United States | G10: USA | J10: United States | Q10: Census division | R10: =COUNTIF('Label Map'!$D$2:$D$2000,A10) -> 2
A11: US East South Central | B11: Sub-national region | C11: Global | D11: AMER | E11: North America (NORAM) | F11: United States | G11: USA | J11: United States | Q11: Census division | R11: =COUNTIF('Label Map'!$D$2:$D$2000,A11) -> 2
A12: US Great Lakes | B12: Sub-national region | C12: Global | D12: AMER | E12: North America (NORAM) | F12: United States | G12: USA | J12: United States | R12: =COUNTIF('Label Map'!$D$2:$D$2000,A12) -> 2
A13: US Gulf Coast | B13: Sub-national region | C13: Global | D13: AMER | E13: North America (NORAM) | F13: United States | G13: USA | J13: United States | R13: =COUNTIF('Label Map'!$D$2:$D$2000,A13) -> 2
A14: US Mid-Atlantic | B14: Sub-national region | C14: Global | D14: AMER | E14: North America (NORAM) | F14: United States | G14: USA | J14: United States | R14: =COUNTIF('Label Map'!$D$2:$D$2000,A14) -> 3
A15: US Mid-South | B15: Sub-national region | C15: Global | D15: AMER | E15: North America (NORAM) | F15: United States | G15: USA | J15: United States | R15: =COUNTIF('Label Map'!$D$2:$D$2000,A15) -> 1
A16: US Midwest | B16: Sub-national region | C16: Global | D16: AMER | E16: North America (NORAM) | F16: United States | G16: USA | J16: United States | R16: =COUNTIF('Label Map'!$D$2:$D$2000,A16) -> 4
A17: US Mountain | B17: Sub-national region | C17: Global | D17: AMER | E17: North America (NORAM) | F17: United States | G17: USA | J17: United States | R17: =COUNTIF('Label Map'!$D$2:$D$2000,A17) -> 4
A18: US New England | B18: Sub-national region | C18: Global | D18: AMER | E18: North America (NORAM) | F18: United States | G18: USA | J18: United States | Q18: Census division | R18: =COUNTIF('Label Map'!$D$2:$D$2000,A18) -> 2
A19: US North | B19: Sub-national region | C19: Global | D19: AMER | E19: North America (NORAM) | F19: United States | G19: USA | J19: United States | R19: =COUNTIF('Label Map'!$D$2:$D$2000,A19) -> 2
A20: US Northeast | B20: Sub-national region | C20: Global | D20: AMER | E20: North America (NORAM) | F20: United States | G20: USA | J20: United States | R20: =COUNTIF('Label Map'!$D$2:$D$2000,A20) -> 3
A21: US Northeast Corridor | B21: Sub-national region | C21: Global | D21: AMER | E21: North America (NORAM) | F21: United States | G21: USA | J21: United States | Q21: Boston–Washington | R21: =COUNTIF('Label Map'!$D$2:$D$2000,A21) -> 1
A22: US Northwest | B22: Sub-national region | C22: Global | D22: AMER | E22: North America (NORAM) | F22: United States | G22: USA | J22: United States | R22: =COUNTIF('Label Map'!$D$2:$D$2000,A22) -> 2
A23: US Pacific | B23: Sub-national region | C23: Global | D23: AMER | E23: North America (NORAM) | F23: United States | G23: USA | J23: United States | Q23: Census division (not Asia Pacific) | R23: =COUNTIF('Label Map'!$D$2:$D$2000,A23) -> 1
A24: US Pacific Northwest | B24: Sub-national region | C24: Global | D24: AMER | E24: North America (NORAM) | F24: United States | G24: USA | J24: United States | R24: =COUNTIF('Label Map'!$D$2:$D$2000,A24) -> 2
A25: US Rust Belt | B25: Sub-national region | C25: Global | D25: AMER | E25: North America (NORAM) | F25: United States | G25: USA | J25: United States | R25: =COUNTIF('Label Map'!$D$2:$D$2000,A25) -> 1
A26: US South | B26: Sub-national region | C26: Global | D26: AMER | E26: North America (NORAM) | F26: United States | G26: USA | J26: United States | R26: =COUNTIF('Label Map'!$D$2:$D$2000,A26) -> 3
A27: US South Atlantic | B27: Sub-national region | C27: Global | D27: AMER | E27: North America (NORAM) | F27: United States | G27: USA | J27: United States | Q27: Census division | R27: =COUNTIF('Label Map'!$D$2:$D$2000,A27) -> 2
A28: US South Central | B28: Sub-national region | C28: Global | D28: AMER | E28: North America (NORAM) | F28: United States | G28: USA | J28: United States | Q28: Assumed US region — confirm | R28: =COUNTIF('Label Map'!$D$2:$D$2000,A28) -> 2
A29: US Southeast | B29: Sub-national region | C29: Global | D29: AMER | E29: North America (NORAM) | F29: United States | G29: USA | J29: United States | R29: =COUNTIF('Label Map'!$D$2:$D$2000,A29) -> 3
A30: US Southwest | B30: Sub-national region | C30: Global | D30: AMER | E30: North America (NORAM) | F30: United States | G30: USA | J30: United States | R30: =COUNTIF('Label Map'!$D$2:$D$2000,A30) -> 2
A31: US Sun Belt | B31: Sub-national region | C31: Global | D31: AMER | E31: North America (NORAM) | F31: United States | G31: USA | J31: United States | R31: =COUNTIF('Label Map'!$D$2:$D$2000,A31) -> 1
A32: US Tri-State Area | B32: Sub-national region | C32: Global | D32: AMER | E32: North America (NORAM) | F32: United States | G32: USA | J32: United States | Q32: New York, New Jersey, Connecticut | R32: =COUNTIF('Label Map'!$D$2:$D$2000,A32) -> 2
A33: US Upper Midwest | B33: Sub-national region | C33: Global | D33: AMER | E33: North America (NORAM) | F33: United States | G33: USA | J33: United States | R33: =COUNTIF('Label Map'!$D$2:$D$2000,A33) -> 1
A34: US Washington Metro (DMV) | B34: Sub-national region | C34: Global | D34: AMER | E34: North America (NORAM) | F34: United States | G34: USA | J34: United States | Q34: DC, Maryland, Virginia | R34: =COUNTIF('Label Map'!$D$2:$D$2000,A34) -> 2
A35: US West | B35: Sub-national region | C35: Global | D35: AMER | E35: North America (NORAM) | F35: United States | G35: USA | J35: United States | R35: =COUNTIF('Label Map'!$D$2:$D$2000,A35) -> 3
A36: US West Coast | B36: Sub-national region | C36: Global | D36: AMER | E36: North America (NORAM) | F36: United States | G36: USA | J36: United States | R36: =COUNTIF('Label Map'!$D$2:$D$2000,A36) -> 2
A37: US West North Central | B37: Sub-national region | C37: Global | D37: AMER | E37: North America (NORAM) | F37: United States | G37: USA | J37: United States | Q37: Census division | R37: =COUNTIF('Label Map'!$D$2:$D$2000,A37) -> 2
A38: US West South Central | B38: Sub-national region | C38: Global | D38: AMER | E38: North America (NORAM) | F38: United States | G38: USA | J38: United States | Q38: Census division | R38: =COUNTIF('Label Map'!$D$2:$D$2000,A38) -> 2
A39: Alabama | B39: State/Province | C39: Global | D39: AMER | E39: North America (NORAM) | F39: United States | G39: USA | H39: Alabama | J39: United States | R39: =COUNTIF('Label Map'!$D$2:$D$2000,A39) -> 2
A40: Alaska | B40: State/Province | C40: Global | D40: AMER | E40: North America (NORAM) | F40: United States | G40: USA | H40: Alaska | J40: United States | R40: =COUNTIF('Label Map'!$D$2:$D$2000,A40) -> 1
...

Sheet Tree View
A1: Global > Region > Sub-region > Country > State/Province (business regions in italics) > City. Names are live links to Hierarchy. Groupings (Nordics, GCC, NOLA…) and non-regional buckets are on Hierarchy only.
A3: Global | B3: Region | C3: Sub-region | D3: Country | E3: State/Province / Region | F3: City | G3: ISO3
A4: =Hierarchy!A2 -> Global
B5: =Hierarchy!A3 -> AMER (Americas)
C6: =Hierarchy!A5 -> North America (NORAM)
D7: =Hierarchy!A6 -> United States | G7: =Hierarchy!G6 -> USA
E8: =Hierarchy!A7 -> US Carolinas
E9: =Hierarchy!A8 -> US Central
E10: =Hierarchy!A9 -> US East
E11: =Hierarchy!A10 -> US East North Central
E12: =Hierarchy!A11 -> US East South Central
E13: =Hierarchy!A12 -> US Great Lakes
E14: =Hierarchy!A13 -> US Gulf Coast
E15: =Hierarchy!A14 -> US Mid-Atlantic
E16: =Hierarchy!A15 -> US Mid-South
E17: =Hierarchy!A16 -> US Midwest
E18: =Hierarchy!A17 -> US Mountain
E19: =Hierarchy!A18 -> US New England
... E43: =Hierarchy!A42 -> Arizona
F44: =Hierarchy!A43 -> Phoenix
F45: =Hierarchy!A44 -> Scottsdale
F46: =Hierarchy!A45 -> Tucson
E47: =Hierarchy!A46 -> Arkansas
F48: =Hierarchy!A47 -> Bentonville
E49: =Hierarchy!A48 -> California
F50: =Hierarchy!A49 -> Greater Los Angeles
F51: =Hierarchy!A50 -> Inland Empire
F52: =Hierarchy!A51 -> Irwindale
F53: =Hierarchy!A52 -> Los Angeles
F54: =Hierarchy!A53 -> Oceanside
F55: =Hierarchy!A54 -> Sacramento
F56: =Hierarchy!A55 -> Sacramento Area
F57: =Hierarchy!A56 -> San Bernardino
F58: =Hierarchy!A57 -> San Diego
F59: =Hierarchy!A58 -> San Francisco
F60: =Hierarchy!A59 -> San Francisco Bay Area
F61: =Hierarchy!A60 -> San Jose
... F64: =Hierarchy!A63 -> Silicon Valley
E65: =Hierarchy!A64 -> Colorado
F66: =Hierarchy!A65 -> Colorado Springs
...

Sheet Label Map
A1: MDP Label (raw) | B1: Source Sheet | C1: Previous MDP Name | D1: Standard Node | E1: Scope | F1: Level | G1: Region | H1: Sub-region | I1: Country | J1: ISO3 | K1: State/Province | L1: City | M1: Change vs Previous | N1: Match Key | O1: Key Conflict | P1: Note
A2: Aargau | B2: Pre-seeded | D2: Aargau | E2: Exact | F2: =IF($D2="","",IFERROR(IF(INDEX(Hierarchy!$B$2:$B$1295,MATCH($D2,Hierarchy!$A$2:$A$1295,0))="","",INDEX(Hierarchy!$B$2:$B$1295,MATCH($D2,Hierarchy!$A$2:$A$1295,0))),"NODE NOT FOUND")) -> State/Province | G2: =IF($D2="","",IFERROR(IF(INDEX(Hierarchy!$D$2:$D$1295,MATCH($D2,Hierarchy!$A$2:$A$1295,0))="","",INDEX(Hierarchy!$D$2:$D$1295,MATCH($D2,Hierarchy!$A$2:$A$1295,0))),"NODE NOT FOUND")) -> EMEA | H2: =IF($D2="","",IFERROR(IF(INDEX(Hierarchy!$E$2:$E$1295,MATCH($D2,Hierarchy!$A$2:$A$1295,0))="","",INDEX(Hierarchy!$E$2:$E$1295,MATCH($D2,Hierarchy!$A$2:$A$1295,0))),"NODE NOT FOUND")) -> Europe | I2: =IF($D2="","",IFERROR(IF(INDEX(Hierarchy!$F$2:$F$1295,MATCH($D2,Hierarchy!$A$2:$A$1295,0))="","",INDEX(Hierarchy!$F$2:$F$1295,MATCH($D2,Hierarchy!$A$2:$A$1295,0))),"NODE NOT FOUND")) -> Switzerland | J2: =IF($D2="","",IFERROR(IF(INDEX(Hierarchy!$G$2:$G$1295,MATCH($D2,Hierarchy!$A$2:$A$1295,0))="","",INDEX(Hierarchy!$G$2:$G$1295,MATCH($D2,Hierarchy!$A$2:$A$1295,0))),"NODE NOT FOUND")) -> CHE | K2: =IF($D2="","",IFERROR(IF(INDEX(Hierarchy!$H$2:$H$1295,MATCH($D2,Hierarchy!$A$2:$A$1295,0))="","",INDEX(Hierarchy!$H$2:$H$1295,MATCH($D2,Hierarchy!$A$2:$A$1295,0))),"NODE NOT FOUND")) -> Aargau | L2: =IF($D2="","",IFERROR(IF(INDEX(Hierarchy!$I$2:$I$1295,MATCH($D2,Hierarchy!$A$2:$A$1295,0))="","",INDEX(Hierarchy!$I$2:$I$1295,MATCH($D2,Hierarchy!$A$2:$A$1295,0))),"NODE NOT FOUND")) | M2: =IF(B2="Pre-seeded","Pre-seeded",IF(B2="Review 2026-09-16","Added from review",IF(C2="","New",IF(C2=D2,"","Changed")))) -> Pre-seeded | N2: =TRIM(SUBSTITUTE(SUBSTITUTE(SUBSTITUTE(" "&TRIM(SUBSTITUTE(SUBSTITUTE(SUBSTITUTE(SUBSTITUTE(SUBSTITUTE(SUBSTITUTE(SUBSTITUTE(SUBSTITUTE(SUBSTITUTE(SUBSTITUTE(SUBSTITUTE(SUBSTITUTE(SUBSTITUTE(SUBSTITUTE(SUBSTITUTE(UPPER(TRIM(A2)),"[MEMBER]",""),"{MEMBER}",""),"[MEMBER}",""),"MEMBER]",""),"(A)",""),"""",""),"“",""),"”",""),".",""),":",""),",",""),"–"," "),"-"," "),"/"," "),"&"," AND "))&" "," THE "," ")," TOTAL "," ")," OPERATIONS "," ")) -> AARGAU | O2: =IF(COUNTIFS($N$2:$N$2000,N2,$D$2:$D$2000,"<>"&D2)>0,"CONFLICT","")
A3: Abia | B3: Pre-seeded | D3: Abia | E3: Exact | F3: =IF($D3="","",IFERROR(IF(INDEX(Hierarchy!$B$2:$B$1295,MATCH($D3,Hierarchy!$A$2:$A$1295,0))="","",INDEX(Hierarchy!$B$2:$B$1295,MATCH($D3,Hierarchy!$A$2:$A$1295,0))),"NODE NOT FOUND")) -> State/Province | G3: =IF($D3="","",IFERROR(IF(INDEX(Hierarchy!$D$2:$D$1295,MATCH($D3,Hierarchy!$A$2:$A$1295,0))="","",INDEX(Hierarchy!$D$2:$D$1295,MATCH($D3,Hierarchy!$A$2:$A$1295,0))),"NODE NOT FOUND")) -> EMEA | H3: =IF($D3="","",IFERROR(IF(INDEX(Hierarchy!$E$2:$E$1295,MATCH($D3,Hierarchy!$A$2:$A$1295,0))="","",INDEX(Hierarchy!$E$2:$E$1295,MATCH($D3,Hierarchy!$A$2:$A$1295,0))),"NODE NOT FOUND")) -> Africa | I3: =IF($D3="","",IFERROR(IF(INDEX(Hierarchy!$F$2:$F$1295,MATCH($D3,Hierarchy!$A$2:$A$1295,0))="","",INDEX(Hierarchy!$F$2:$F$1295,MATCH($D3,Hierarchy!$A$2:$A$1295,0))),"NODE NOT FOUND")) -> Nigeria | J3: =IF($D3="","",IFERROR(IF(INDEX(Hierarchy!$G$2:$G$1295,MATCH($D3,Hierarchy!$A$2:$A$1295,0))="","",INDEX(Hierarchy!$G$2:$G$1295,MATCH($D3,Hierarchy!$A$2:$A$1295,0))),"NODE NOT FOUND")) -> NGA | K3: =IF($D3="","",IFERROR(IF(INDEX(Hierarchy!$H$2:$H$1295,MATCH($D3,Hierarchy!$A$2:$A$1295,0))="","",INDEX(Hierarchy!$H$2:$H$1295,MATCH($D3,Hierarchy!$A$2:$A$1295,0))),"NODE NOT FOUND")) -> Abia | L3: =IF($D3="","",IFERROR(IF(INDEX(Hierarchy!$I$2:$I$1295,MATCH($D3,Hierarchy!$A$2:$A$1295,0))="","",INDEX(Hierarchy!$I$2:$I$1295,MATCH($D3,Hierarchy!$A$2:$A$1295,0))),"NODE NOT FOUND")) | M3: =IF(B3="Pre-seeded","Pre-seeded",IF(B3="Review 2026-09-16","Added from review",IF(C3="","New",IF(C3=D3,"","Changed")))) -> Pre-seeded | N3: =TRIM(SUBSTITUTE(SUBSTITUTE(SUBSTITUTE(" "&TRIM(SUBSTITUTE(SUBSTITUTE(SUBSTITUTE(SUBSTITUTE(SUBSTITUTE(SUBSTITUTE(SUBSTITUTE(SUBSTITUTE(SUBSTITUTE(SUBSTITUTE(SUBSTITUTE(SUBSTITUTE(SUBSTITUTE(SUBSTITUTE(SUBSTITUTE(UPPER(TRIM(A3)),"[MEMBER]",""),"{MEMBER}",""),"[MEMBER}",""),"MEMBER]",""),"(A)",""),"""",""),"“",""),"”",""),".",""),":",""),",",""),"–"," "),"-"," "),"/"," "),"&"," AND "))&" "," THE "," ")," TOTAL "," ")," OPERATIONS "," ")) -> ABIA | O3: =IF(COUNTIFS($N$2:$N$2000,N3,$D$2:$D$2000,"<>"&D3)>0,"CONFLICT","")
A4: Abroad | B4: Pre-seeded | D4: International | E4: Exact | F4: =IF($D4="","",IFERROR(IF(INDEX(Hierarchy!$B$2:$B$1295,MATCH($D4,Hierarchy!$A$2:$A$1295,0))="","",INDEX(Hierarchy!$B$2:$B$1295,MATCH($D4,Hierarchy!$A$2:$A$1295,0))),"NODE NOT FOUND")) -> Bucket | G4: =IF($D4="","",IFERROR(IF(INDEX(Hierarchy!$D$2:$D$1295,MATCH($D4,Hierarchy!$A$2:$A$1295,0))="","",INDEX(Hierarchy!$D$2:$D$1295,MATCH($D4,Hierarchy!$A$2:$A$1295,0))),"NODE NOT FOUND")) -> Non-regional | H4: =IF($D4="","",IFERROR(IF(INDEX(Hierarchy!$E$2:$E$1295,MATCH($D4,Hierarchy!$A$2:$A$1295,0))="","",INDEX(Hierarchy!$E$2:$E$1295,MATCH($D4,Hierarchy!$A$2:$A$1295,0))),"NODE NOT FOUND")) | I4: =IF($D4="","",IFERROR(IF(INDEX(Hierarchy!$F$2:$F$1295,MATCH($D4,Hierarchy!$A$2:$A$1295,0))="","",INDEX(Hierarchy!$F$2:$F$1295,MATCH($D4,Hierarchy!$A$2:$A$1295,0))),"NODE NOT FOUND")) | J4: =IF($D4="","",IFERROR(IF(INDEX(Hierarchy!$G$2:$G$1295,MATCH($D4,Hierarchy!$A$2:$A$1295,0))="","",INDEX(Hierarchy!$G$2:$G$1295,MATCH($D4,Hierarchy!$A$2:$A$1295,0))),"NODE NOT FOUND")) | K4: =IF($D4="","",IFERROR(IF(INDEX(Hierarchy!$H$2:$H$1295,MATCH($D4,Hierarchy!$A$2:$A$1295,0))="","",INDEX(Hierarchy!$H$2:$H$1295,MATCH($D4,Hierarchy!$A$2:$A$1295,0))),"NODE NOT FOUND")) | L4: =IF($D4="","",IFERROR(IF(INDEX(Hierarchy!$I$2:$I$1295,MATCH($D4,Hierarchy!$A$2:$A$1295,0))="","",INDEX(Hierarchy!$I$2:$I$1295,MATCH($D4,Hierarchy!$A$2:$A$1295,0))),"NODE NOT FOUND")) | M4: =IF(B4="Pre-seeded","Pre-seeded",IF(B4="Review 2026-09-16","Added from review",IF(C4="","New",IF(C4=D4,"","Changed")))) -> Pre-seeded | N4: =TRIM(SUBSTITUTE(SUBSTITUTE(SUBSTITUTE(" "&TRIM(SUBSTITUTE(SUBSTITUTE(SUBSTITUTE(SUBSTITUTE(SUBSTITUTE(SUBSTITUTE(SUBSTITUTE(SUBSTITUTE(SUBSTITUTE(SUBSTITUTE(SUBSTITUTE(SUBSTITUTE(SUBSTITUTE(SUBSTITUTE(SUBSTITUTE(UPPER(TRIM(A4)),"[MEMBER]",""),"{MEMBER}",""),"[MEMBER}",""),"MEMBER]",""),"(A)",""),"""",""),"“",""),"”",""),".",""),":",""),",",""),"–"," "),"-"," "),"/"," "),"&"," AND "))&" "," THE "," ")," TOTAL "," ")," OPERATIONS "," ")) -> ABROAD | O4: =IF(COUNTIFS($N$2:$N$2000,N4,$D$2:$D$2000,"<>"&D4)>0,"CONFLICT","")
A5: Abruzzo | B5: Pre-seeded | D5: Abruzzo | E5: Exact | F5: =IF($D5="","",IFERROR(IF(INDEX(Hierarchy!$B$2:$B$1295,MATCH($D5,Hierarchy!$A$2:$A$1295,0))="","",INDEX(Hierarchy!$B$2:$B$1295,MATCH($D5,Hierarchy!$A$2:$A$1295,0))),"NODE NOT FOUND")) -> State/Province | G5: =IF($D5="","",IFERROR(IF(INDEX(Hierarchy!$D$2:$D$1295,MATCH($D5,Hierarchy!$A$2:$A$1295,0))="","",INDEX(Hierarchy!$D$2:$D$1295,MATCH($D5,Hierarchy!$A$2:$A$1295,0))),"NODE NOT FOUND")) -> EMEA | H5: =IF($D5="","",IFERROR(IF(INDEX(Hierarchy!$E$2:$E$1295,MATCH($D5,Hierarchy!$A$2:$A$1295,0))="","",INDEX(Hierarchy!$E$2:$E$1295,MATCH($D5,Hierarchy!$A$2:$A$1295,0))),"NODE NOT FOUND")) -> Europe | I5: =IF($D5="","",IFERROR(IF(INDEX(Hierarchy!$F$2:$F$1295,MATCH($D5,Hierarchy!$A$2:$A$1295,0))="","",INDEX(Hierarchy!$F$2:$F$1295,MATCH($D5,Hierarchy!$A$2:$A$1295,0))),"NODE NOT FOUND")) -> Italy | J5: =IF($D5="","",IFERROR(IF(INDEX(Hierarchy!$G$2:$G$1295,MATCH($D5,Hierarchy!$A$2:$A$1295,0))="","",INDEX(Hierarchy!$G$2:$G$1295,MATCH($D5,Hierarchy!$A$2:$A$1295,0))),"NODE NOT FOUND")) -> ITA | K5: =IF($D5="","",IFERROR(IF(INDEX(Hierarchy!$H$2:$H$1295,MATCH($D5,Hierarchy!$A$2:$A$1295,0))="","",INDEX(Hierarchy!$H$2:$H$1295,MATCH($D5,Hierarchy!$A$2:$A$1295,0))),"NODE NOT FOUND")) -> Abruzzo | L5: =IF($D5="","",IFERROR(IF(INDEX(Hierarchy!$I$2:$I$1295,MATCH($D5,Hierarchy!$A$2:$A$1295,0))="","",INDEX(Hierarchy!$I$2:$I$1295,MATCH($D5,Hierarchy!$A$2:$A$1295,0))),"NODE NOT FOUND")) | M5: =IF(B5="Pre-seeded","Pre-seeded",IF(B5="Review 2026-09-16","Added from review",IF(C5="","New",IF(C5=D5,"","Changed")))) -> Pre-seeded | N5: =TRIM(SUBSTITUTE(SUBSTITUTE(SUBSTITUTE(" "&TRIM(SUBSTITUTE(SUBSTITUTE(SUBSTITUTE(SUBSTITUTE(SUBSTITUTE(SUBSTITUTE(SUBSTITUTE(SUBSTITUTE(SUBSTITUTE(SUBSTITUTE(SUBSTITUTE(SUBSTITUTE(SUBSTITUTE(SUBSTITUTE(SUBSTITUTE(UPPER(TRIM(A5)),"[MEMBER]",""),"{MEMBER}",""),"[MEMBER}",""),"MEMBER]",""),"(A)",""),"""",""),"“",""),"”",""),".",""),":",""),",",""),"–"," "),"-"," "),"/"," "),"&"," AND "))&" "," THE "," ")," TOTAL "," ")," OPERATIONS "," ")) -> ABRUZZO | O5: =IF(COUNTIFS($N$2:$N$2000,N5,$D$2:$D$2000,"<>"&D5)>0,"CONFLICT","")
A6: Abu Dhabi | B6: Mapping | C6: Abu Dhabi | D6: Abu Dhabi | E6: Exact | F6: =IF($D6="","",IFERROR(IF(INDEX(Hierarchy!$B$2:$B$1295,MATCH($D6,Hierarchy!$A$2:$A$1295,0))="","",INDEX(Hierarchy!$B$2:$B$1295,MATCH($D6,Hierarchy!$A$2:$A$1295,0))),"NODE NOT FOUND")) -> State/Province | G6: =IF($D6="","",IFERROR(IF(INDEX(Hierarchy!$D$2:$D$1295,MATCH($D6,Hierarchy!$A$2:$A$1295,0))="","",INDEX(Hierarchy!$D$2:$D$1295,MATCH($D6,Hierarchy!$A$2:$A$1295,0))),"NODE NOT FOUND")) -> EMEA | H6: =IF($D6="","",IFERROR(IF(INDEX(Hierarchy!$E$2:$E$1295,MATCH($D6,Hierarchy!$A$2:$A$1295,0))="","",INDEX(Hierarchy!$E$2:$E$1295,MATCH($D6,Hierarchy!$A$2:$A$1295,0))),"NODE NOT FOUND")) -> Middle East | I6: =IF($D6="","",IFERROR(IF(INDEX(Hierarchy!$F$2:$F$1295,MATCH($D6,Hierarchy!$A$2:$A$1295,0))="","",INDEX(Hierarchy!$F$2:$F$1295,MATCH($D6,Hierarchy!$A$2:$A$1295,0))),"NODE NOT FOUND")) -> United Arab Emirates | J6: =IF($D6="","",IFERROR(IF(INDEX(Hierarchy!$G$2:$G$1295,MATCH($D6,Hierarchy!$A$2:$A$1295,0))="","",INDEX(Hierarchy!$G$2:$G$1295,MATCH($D6,Hierarchy!$A$2:$A$1295,0))),"NODE NOT FOUND")) -> ARE | K6: =IF($D6="","",IFERROR(IF(INDEX(Hierarchy!$H$2:$H$1295,MATCH($D6,Hierarchy!$A$2:$A$1295,0))="","",INDEX(Hierarchy!$H$2:$H$1295,MATCH($D6,Hierarchy!$A$2:$A$1295,0))),"NODE NOT FOUND")) -> Abu Dhabi | L6: =IF($D6="","",IFERROR(IF(INDEX(Hierarchy!$I$2:$I$1295,MATCH($D6,Hierarchy!$A$2:$A$1295,0))="","",INDEX(Hierarchy!$I$2:$I$1295,MATCH($D6,Hierarchy!$A$2:$A$1295,0))),"NODE NOT FOUND")) | M6: =IF(B6="Pre-seeded","Pre-seeded",IF(B6="Review 2026-09-16","Added from review",IF(C6="","New",IF(C6=D6,"","Changed")))) | N6: =TRIM(SUBSTITUTE(SUBSTITUTE(SUBSTITUTE(" "&TRIM(SUBSTITUTE(SUBSTITUTE(SUBSTITUTE(SUBSTITUTE(SUBSTITUTE(SUBSTITUTE(SUBSTITUTE(SUBSTITUTE(SUBSTITUTE(SUBSTITUTE(SUBSTITUTE(SUBSTITUTE(SUBSTITUTE(SUBSTITUTE(SUBSTITUTE(UPPER(TRIM(A6)),"[MEMBER]",""),"{MEMBER}",""),"[MEMBER}",""),"MEMBER]",""),"(A)",""),"""",""),"“",""),"”",""),".",""),":",""),",",""),"–"," "),"-"," "),"/"," "),"&"," AND "))&" "," THE "," ")," TOTAL "," ")," OPERATIONS "," ")) -> ABU DHABI | O6: =IF(COUNTIFS($N$2:$N$2000,N6,$D$2:$D$2000,"<>"&D6)>0,"CONFLICT","")
A7: Abuja | B7: Pre-seeded | D7: Federal Capital Territory (Abuja) | E7: Exact | F7: =IF($D7="","",IFERROR(IF(INDEX(Hierarchy!$B$2:$B$1295,MATCH($D7,Hierarchy!$A$2:$A$1295,0))="","",INDEX(Hierarchy!$B$2:$B$1295,MATCH($D7,Hierarchy!$A$2:$A$1295,0))),"NODE NOT FOUND")) -> State/Province | G7: =IF($D7="","",IFERROR(IF(INDEX(Hierarchy!$D$2:$D$1295,MATCH($D7,Hierarchy!$A$2:$A$1295,0))="","",INDEX(Hierarchy!$D$2:$D$1295,MATCH($D7,Hierarchy!$A$2:$A$1295,0))),"NODE NOT FOUND")) -> EMEA | H7: =IF($D7="","",IFERROR(IF(INDEX(Hierarchy!$E$2:$E$1295,MATCH($D7,Hierarchy!$A$2:$A$1295,0))="","",INDEX(Hierarchy!$E$2:$E$1295,MATCH($D7,Hierarchy!$A$2:$A$1295,0))),"NODE NOT FOUND")) -> Africa | I7: =IF($D7="","",IFERROR(IF(INDEX(Hierarchy!$F$2:$F$1295,MATCH($D7,Hierarchy!$A$2:$A$1295,0))="","",INDEX(Hierarchy!$F$2:$F$1295,MATCH($D7,Hierarchy!$A$2:$A$1295,0))),"NODE NOT FOUND")) -> Nigeria | J7: =IF($D7="","",IFERROR(IF(INDEX(Hierarchy!$G$2:$G$1295,MATCH($D7,Hierarchy!$A$2:$A$1295,0))="","",INDEX(Hierarchy!$G$2:$G$1295,MATCH($D7,Hierarchy!$A$2:$A$1295,0))),"NODE NOT FOUND")) -> NGA | K7: =IF($D7="","",IFERROR(IF(INDEX(Hierarchy!$H$2:$H$1295,MATCH($D7,Hierarchy!$A$2:$A$1295,0))="","",INDEX(Hierarchy!$H$2:$H$1295,MATCH($D7,Hierarchy!$A$2:$A$1295,0))),"NODE NOT FOUND")) -> Federal Capital Territory (Abuja) | L7: =IF($D7="","",IFERROR(IF(INDEX(Hierarchy!$I$2:$I$1295,MATCH($D7,Hierarchy!$A$2:$A$1295,0))="","",INDEX(Hierarchy!$I$2:$I$1295,MATCH($D7,Hierarchy!$A$2:$A$1295,0))),"NODE NOT FOUND")) | M7: =IF(B7="Pre-seeded","Pre-seeded",IF(B7="Review 2026-09-16","Added from review",IF(C7="","New",IF(C7=D7,"","Changed")))) -> Pre-seeded | N7: =TRIM(SUBSTITUTE(SUBSTITUTE(SUBSTITUTE(" "&TRIM(SUBSTITUTE(SUBSTITUTE(SUBSTITUTE(SUBSTITUTE(SUBSTITUTE(SUBSTITUTE(SUBSTITUTE(SUBSTITUTE(SUBSTITUTE(SUBSTITUTE(SUBSTITUTE(SUBSTITUTE(SUBSTITUTE(SUBSTITUTE(SUBSTITUTE(UPPER(TRIM(A7)),"[MEMBER]",""),"{MEMBER}",""),"[MEMBER}",""),"MEMBER]",""),"(A)",""),"""",""),"“",""),"”",""),".",""),":",""),",",""),"–"," "),"-"," "),"/"," "),"&"," AND "))&" "," THE "," ")," TOTAL "," ")," OPERATIONS "," ")) -> ABUJA | O7: =IF(COUNTIFS($N$2:$N$2000,N7,$D$2:$D$2000,"<>"&D7)>0,"CONFLICT","")
A8: Aceh | B8: Pre-seeded | D8: Aceh | E8: Exact | F8: =IF($D8="","",IFERROR(IF(INDEX(Hierarchy!$B$2:$B$1295,MATCH($D8,Hierarchy!$A$2:$A$1295,0))="","",INDEX(Hierarchy!$B$2:$B$1295,MATCH($D8,Hierarchy!$A$2:$A$1295,0))),"NODE NOT FOUND")) -> State/Province | G8: =IF($D8="","",IFERROR(IF(INDEX(Hierarchy!$D$2:$D$1295,MATCH($D8,Hierarchy!$A$2:$A$1295,0))="","",INDEX(Hierarchy!$D$2:$D$1295,MATCH($D8,Hierarchy!$A$2:$A$1295,0))),"NODE NOT FOUND")) -> APAC | H8: =IF($D8="","",IFERROR(IF(INDEX(Hierarchy!$E$2:$E$1295,MATCH($D8,Hierarchy!$A$2:$A$1295,0))="","",INDEX(Hierarchy!$E$2:$E$1295,MATCH($D8,Hierarchy!$A$2:$A$1295,0))),"NODE NOT FOUND")) -> Southeast Asia (ASEAN) | I8: =IF($D8="","",IFERROR(IF(INDEX(Hierarchy!$F$2:$F$1295,MATCH($D8,Hierarchy!$A$2:$A$1295,0))="","",INDEX(Hierarchy!$F$2:$F$1295,MATCH($D8,Hierarchy!$A$2:$A$1295,0))),"NODE NOT FOUND")) -> Indonesia | J8: =IF($D8="","",IFERROR(IF(INDEX(Hierarchy!$G$2:$G$1295,MATCH($D8,Hierarchy!$A$2:$A$1295,0))="","",INDEX(Hierarchy!$G$2:$G$1295,MATCH($D8,Hierarchy!$A$2:$A$1295,0))),"NODE NOT FOUND")) -> IDN | K8: =IF($D8="","",IFERROR(IF(INDEX(Hierarchy!$H$2:$H$1295,MATCH($D8,Hierarchy!$A$2:$A$1295,0))="","",INDEX(Hierarchy!$H$2:$H$1295,MATCH($D8,Hierarchy!$A$2:$A$1295,0))),"NODE NOT FOUND")) -> Aceh | L8: =IF($D8="","",IFERROR(IF(INDEX(Hierarchy!$I$2:$I$1295,MATCH($D8,Hierarchy!$A$2:$A$1295,0))="","",INDEX(Hierarchy!$I$2:$I$1295,MATCH($D8,Hierarchy!$A$2:$A$1295,0))),"NODE NOT FOUND")) | M8: =IF(B8="Pre-seeded","Pre-seeded",IF(B8="Review 2026-09-16","Added from review",IF(C8="","New",IF(C8=D8,"","Changed")))) -> Pre-seeded | N8: =TRIM(SUBSTITUTE(SUBSTITUTE(SUBSTITUTE(" "&TRIM(SUBSTITUTE(SUBSTITUTE(SUBSTITUTE(SUBSTITUTE(SUBSTITUTE(SUBSTITUTE(SUBSTITUTE(SUBSTITUTE(SUBSTITUTE(SUBSTITUTE(SUBSTITUTE(SUBSTITUTE(SUBSTITUTE(SUBSTITUTE(SUBSTITUTE(UPPER(TRIM(A8)),"[MEMBER]",""),"{MEMBER}",""),"[MEMBER}",""),"MEMBER]",""),"(A)",""),"""",""),"“",""),"”",""),".",""),":",""),",",""),"–"," "),"-"," "),"/"," "),"&"," AND "))&" "," THE "," ")," TOTAL "," ")," OPERATIONS "," ")) -> ACEH | O8: =IF(COUNTIFS($N$2:$N$2000,N8,$D$2:$D$2000,"<>"&D8)>0,"CONFLICT","")
A9: Acre | B9: Pre-seeded | D9: Acre | E9: Exact | F9: =IF($D9="","",IFERROR(IF(INDEX(Hierarchy!$B$2:$B$1295,MATCH($D9,Hierarchy!$A$2:$A$1295,0))="","",INDEX(Hierarchy!$B$2:$B$1295,MATCH($D9,Hierarchy!$A$2:$A$1295,0))),"NODE NOT FOUND")) -> State/Province | G9: =IF($D9="","",IFERROR(IF(INDEX(Hierarchy!$D$2:$D$1295,MATCH($D9,Hierarchy!$A$2:$A$1295,0))="","",INDEX(Hierarchy!$D$2:$D$1295,MATCH($D9,Hierarchy!$A$2:$A$1295,0))),"NODE NOT FOUND")) -> AMER | H9: =IF($D9="","",IFERROR(IF(INDEX(Hierarchy!$E$2:$E$1295,MATCH($D9,Hierarchy!$A$2:$A$1295,0))="","",INDEX(Hierarchy!$E$2:$E$1295,MATCH($D9,Hierarchy!$A$2:$A$1295,0))),"NODE NOT FOUND")) -> Latin America (LATAM) | I9: =IF($D9="","",IFERROR(IF(INDEX(Hierarchy!$F$2:$F$1295,MATCH($D9,Hierarchy!$A$2:$A$1295,0))="","",INDEX(Hierarchy!$F$2:$F$1295,MATCH($D9,Hierarchy!$A$2:$A$1295,0))),"NODE NOT FOUND")) -> Brazil | J9: =IF($D9="","",IFERROR(IF(INDEX(Hierarchy!$G$2:$G$1295,MATCH($D9,Hierarchy!$A$2:$A$1295,0))="","",INDEX(Hierarchy!$G$2:$G$1295,MATCH($D9,Hierarchy!$A$2:$A$1295,0))),"NODE NOT FOUND")) -> BRA | K9: =IF($D9="","",IFERROR(IF(INDEX(Hierarchy!$H$2:$H$1295,MATCH($D9,Hierarchy!$A$2:$A$1295,0))="","",INDEX(Hierarchy!$H$2:$H$1295,MATCH($D9,Hierarchy!$A$2:$A$1295,0))),"NODE NOT FOUND")) -> Acre | L9: =IF($D9="","",IFERROR(IF(INDEX(Hierarchy!$I$2:$I$1295,MATCH($D9,Hierarchy!$A$2:$A$1295,0))="","",INDEX(Hierarchy!$I$2:$I$1295,MATCH($D9,Hierarchy!$A$2:$A$1295,0))),"NODE NOT FOUND")) | M9: =IF(B9="Pre-seeded","Pre-seeded",IF(B9="Review 2026-09-16","Added from review",IF(C9="","New",IF(C9=D9,"","Changed")))) -> Pre-seeded | N9: =TRIM(SUBSTITUTE(SUBSTITUTE(SUBSTITUTE(" "&TRIM(SUBSTITUTE(SUBSTITUTE(SUBSTITUTE(SUBSTITUTE(SUBSTITUTE(SUBSTITUTE(SUBSTITUTE(SUBSTITUTE(SUBSTITUTE(SUBSTITUTE(SUBSTITUTE(SUBSTITUTE(SUBSTITUTE(SUBSTITUTE(SUBSTITUTE(UPPER(TRIM(A9)),"[MEMBER]",""),"{MEMBER}",""),"[MEMBER}",""),"MEMBER]",""),"(A)",""),"""",""),"“",""),"”",""),".",""),":",""),",",""),"–"," "),"-"," "),"/"," "),"&"," AND "))&" "," THE "," ")," TOTAL "," ")," OPERATIONS "," ")) -> ACRE | O9: =IF(COUNTIFS($N$2:$N$2000,N9,$D$2:$D$2000,"<>"&D9)>0,"CONFLICT","")
A10: Adamawa | B10: Pre-seeded | D10: Adamawa | E10: Exact | F10: =IF($D10="","",IFERROR(IF(INDEX(Hierarchy!$B$2:$B$1295,MATCH($D10,Hierarchy!$A$2:$A$1295,0))="","",INDEX(Hierarchy!$B$2:$B$1295,MATCH($D10,Hierarchy!$A$2:$A$1295,0))),"NODE NOT FOUND")) -> State/Province | G10: =IF($D10="","",IFERROR(IF(INDEX(Hierarchy!$D$2:$D$1295,MATCH($D10,Hierarchy!$A$2:$A$1295,0))="","",INDEX(Hierarchy!$D$2:$D$1295,MATCH($D10,Hierarchy!$A$2:$A$1295,0))),"NODE NOT FOUND")) -> EMEA | H10: =IF($D10="","",IFERROR(IF(INDEX(Hierarchy!$E$2:$E$1295,MATCH($D10,Hierarchy!$A$2:$A$1295,0))="","",INDEX(Hierarchy!$E$2:$E$1295,MATCH($D10,Hierarchy!$A$2:$A$1295,0))),"NODE NOT FOUND")) -> Africa | I10: =IF($D10="","",IFERROR(IF(INDEX(Hierarchy!$F$2:$F$1295,MATCH($D10,Hierarchy!$A$2:$A$1295,0))="","",INDEX(Hierarchy!$F$2:$F$1295,MATCH($D10,Hierarchy!$A$2:$A$1295,0))),"NODE NOT FOUND")) -> Nigeria | J10: =IF($D10="","",IFERROR(IF(INDEX(Hierarchy!$G$2:$G$1295,MATCH($D10,Hierarchy!$A$2:$A$1295,0))="","",INDEX(Hierarchy!$G$2:$G$1295,MATCH($D10,Hierarchy!$A$2:$A$1295,0))),"NODE NOT FOUND")) -> NGA | K10: =IF($D10="","",IFERROR(IF(INDEX(Hierarchy!$H$2:$H$1295,MATCH($D10,Hierarchy!$A$2:$A$1295,0))="","",INDEX(Hierarchy!$H$2:$H$1295,MATCH($D10,Hierarchy!$A$2:$A$1295,0))),"NODE NOT FOUND")) -> Adamawa | L10: =IF($D10="","",IFERROR(IF(INDEX(Hierarchy!$I$2:$I$1295,MATCH($D10,Hierarchy!$A$2:$A$1295,0))="","",INDEX(Hierarchy!$I$2:$I$1295,MATCH($D10,Hierarchy!$A$2:$A$1295,0))),"NODE NOT FOUND")) | M10: =IF(B10="Pre-seeded","Pre-seeded",IF(B10="Review 2026-09-16","Added from review",IF(C10="","New",IF(C10=D10,"","Changed")))) -> Pre-seeded | N10: =TRIM(SUBSTITUTE(SUBSTITUTE(SUBSTITUTE(" "&TRIM(SUBSTITUTE(SUBSTITUTE(SUBSTITUTE(SUBSTITUTE(SUBSTITUTE(SUBSTITUTE(SUBSTITUTE(SUBSTITUTE(SUBSTITUTE(SUBSTITUTE(SUBSTITUTE(SUBSTITUTE(SUBSTITUTE(SUBSTITUTE(SUBSTITUTE(UPPER(TRIM(A10)),"[MEMBER]",""),"{MEMBER}",""),"[MEMBER}",""),"MEMBER]",""),"(A)",""),"""",""),"“",""),"”",""),".",""),":",""),",",""),"–"," "),"-"," "),"/"," "),"&"," AND "))&" "," THE "," ")," TOTAL "," ")," OPERATIONS "," ")) -> ADAMAWA | O10: =IF(COUNTIFS($N$2:$N$2000,N10,$D$2:$D$2000,"<>"&D10)>0,"CONFLICT","")
A11: Afghanistan | B11: Pre-seeded | D11: Afghanistan | E11: Exact | F11: =IF($D11="","",IFERROR(IF(INDEX(Hierarchy!$B$2:$B$1295,MATCH($D11,Hierarchy!$A$2:$A$1295,0))="","",INDEX(Hierarchy!$B$2:$B$1295,MATCH($D11,Hierarchy!$A$2:$A$1295,0))),"NODE NOT FOUND")) -> Country | G11: =IF($D11="","",IFERROR(IF(INDEX(Hierarchy!$D$2:$D$1295,MATCH($D11,Hierarchy!$A$2:$A$1295,0))="","",INDEX(Hierarchy!$D$2:$D$1295,MATCH($D11,Hierarchy!$A$2:$A$1295,0))),"NODE NOT FOUND")) -> APAC | H11: =IF($D11="","",IFERROR(IF(INDEX(Hierarchy!$E$2:$E$1295,MATCH($D11,Hierarchy!$A$2:$A$1295,0))="","",INDEX(Hierarchy!$E$2:$E$1295,MATCH($D11,Hierarchy!$A$2:$A$1295,0))),"NODE NOT FOUND")) -> South Asia | I11: =IF($D11="","",IFERROR(IF(INDEX(Hierarchy!$F$2:$F$1295,MATCH($D11,Hierarchy!$A$2:$A$1295,0))="","",INDEX(Hierarchy!$F$2:$F$1295,MATCH($D11,Hierarchy!$A$2:$A$1295,0))),"NODE NOT FOUND")) -> Afghanistan | J11: =IF($D11="","",IFERROR(IF(INDEX(Hierarchy!$G$2:$G$1295,MATCH($D11,Hierarchy!$A$2:$A$1295,0))="","",INDEX(Hierarchy!$G$2:$G$1295,MATCH($D11,Hierarchy!$A$2:$A$1295,0))),"NODE NOT FOUND")) -> AFG | K11: =IF($D11="","",IFERROR(IF(INDEX(Hierarchy!$H$2:$H$1295,MATCH($D11,Hierarchy!$A$2:$A$1295,0))="","",INDEX(Hierarchy!$H$2:$H$1295,MATCH($D11,Hierarchy!$A$2:$A$1295,0))),"NODE NOT FOUND")) | L11: =IF($D11="","",IFERROR(IF(INDEX(Hierarchy!$I$2:$I$1295,MATCH($D11,Hierarchy!$A$2:$A$1295,0))="","",INDEX(Hierarchy!$I$2:$I$1295,MATCH($D11,Hierarchy!$A$2:$A$1295,0))),"NODE NOT FOUND")) | M11: =IF(B11="Pre-seeded","Pre-seeded",IF(B11="Review 2026-09-16","Added from review",IF(C11="","New",IF(C11=D11,"","Changed")))) -> Pre-seeded | N11: =TRIM(SUBSTITUTE(SUBSTITUTE(SUBSTITUTE(" "&TRIM(SUBSTITUTE(SUBSTITUTE(SUBSTITUTE(SUBSTITUTE(SUBSTITUTE(SUBSTITUTE(SUBSTITUTE(SUBSTITUTE(SUBSTITUTE(SUBSTITUTE(SUBSTITUTE(SUBSTITUTE(SUBSTITUTE(SUBSTITUTE(SUBSTITUTE(UPPER(TRIM(A11)),"[MEMBER]",""),"{MEMBER}",""),"[MEMBER}",""),"MEMBER]",""),"(A)",""),"""",""),"“",""),"”",""),".",""),":",""),",",""),"–"," "),"-"," "),"/"," "),"&"," AND "))&" "," THE "," ")," TOTAL "," ")," OPERATIONS "," ")) -> AFGHANISTAN | O11: =IF(COUNTIFS($N$2:$N$2000,N11,$D$2:$D$2000,"<>"&D11)>0,"CONFLICT","")
A12: Africa | B12: Mapping | C12: Africa | D12: Africa | E12: Exact | F12: =IF($D12="","",IFERROR(IF(INDEX(Hierarchy!$B$2:$B$1295,MATCH($D12,Hierarchy!$A$2:$A$1295,0))="","",INDEX(Hierarchy!$B$2:$B$1295,MATCH($D12,Hierarchy!$A$2:$A$1295,0))),"NODE NOT FOUND")) -> Sub-region | G12: =IF($D12="","",IFERROR(IF(INDEX(Hierarchy!$D$2:$D$1295,MATCH($D12,Hierarchy!$A$2:$A$1295,0))="","",INDEX(Hierarchy!$D$2:$D$1295,MATCH($D12,Hierarchy!$A$2:$A$1295,0))),"NODE NOT FOUND")) -> EMEA | H12: =IF($D12="","",IFERROR(IF(INDEX(Hierarchy!$E$2:$E$1295,MATCH($D12,Hierarchy!$A$2:$A$1295,0))="","",INDEX(Hierarchy!$E$2:$E$1295,MATCH($D12,Hierarchy!$A$2:$A$1295,0))),"NODE NOT FOUND")) -> Africa | I12: =IF($D12="","",IFERROR(IF(INDEX(Hierarchy!$F$2:$F$1295,MATCH($D12,Hierarchy!$A$2:$A$1295,0))="","",INDEX(Hierarchy!$F$2:$F$1295,MATCH($D12,Hierarchy!$A$2:$A$1295,0))),"NODE NOT FOUND")) | J12: =IF($D12="","",IFERROR(IF(INDEX(Hierarchy!$G$2:$G$1295,MATCH($D12,Hierarchy!$A$2:$A$1295,0))="","",INDEX(Hierarchy!$G$2:$G$1295,MATCH($D12,Hierarchy!$A$2:$A$1295,0))),"NODE NOT FOUND")) | K12: =IF($D12="","",IFERROR(IF(INDEX(Hierarchy!$H$2:$H$1295,MATCH($D12,Hierarchy!$A$2:$A$1295,0))="","",INDEX(Hierarchy!$H$2:$H$1295,MATCH($D12,Hierarchy!$A$2:$A$1295,0))),"NODE NOT FOUND")) | L12: =IF($D12="","",IFERROR(IF(INDEX(Hierarchy!$I$2:$I$1295,MATCH($D12,Hierarchy!$A$2:$A$1295,0))="","",INDEX(Hierarchy!$I$2:$I$1295,MATCH($D12,Hierarchy!$A$2:$A$1295,0))),"NODE NOT FOUND")) | M12: =IF(B12="Pre-seeded","Pre-seeded",IF(B12="Review 2026-09-16","Added from review",IF(C12="","New",IF(C12=D12,"","Changed")))) | N12: =TRIM(SUBSTITUTE(SUBSTITUTE(SUBSTITUTE(" "&TRIM(SUBSTITUTE(SUBSTITUTE(SUBSTITUTE(SUBSTITUTE(SUBSTITUTE(SUBSTITUTE(SUBSTITUTE(SUBSTITUTE(SUBSTITUTE(SUBSTITUTE(SUBSTITUTE(SUBSTITUTE(SUBSTITUTE(SUBSTITUTE(SUBSTITUTE(UPPER(TRIM(A12)),"[MEMBER]",""),"{MEMBER}",""),"[MEMBER}",""),"MEMBER]",""),"(A)",""),"""",""),"“",""),"”",""),".",""),":",""),",",""),"–"," "),"-"," "),"/"," "),"&"," AND "))&" "," THE "," ")," TOTAL "," ")," OPERATIONS "," ")) -> AFRICA | O12: =IF(COUNTIFS($N$2:$N$2000,N12,$D$2:$D$2000,"<>"&D12)>0,"CONFLICT","")
A13: Africa/Eurasia | B13: final | C13: Africa | D13: Multi-region (Other) | E13: Combined | F13: =IF($D13="","",IFERROR(IF(INDEX(Hierarchy!$B$2:$B$1295,MATCH($D13,Hierarchy!$A$2:$A$1295,0))="","",INDEX(Hierarchy!$B$2:$B$1295,MATCH($D13,Hierarchy!$A$2:$A$1295,0))),"NODE NOT FOUND")) -> Multi-region | G13: =IF($D13="","",IFERROR(IF(INDEX(Hierarchy!$D$2:$D$1295,MATCH($D13,Hierarchy!$A$2:$A$1295,0))="","",INDEX(Hierarchy!$D$2:$D$1295,MATCH($D13,Hierarchy!$A$2:$A$1295,0))),"NODE NOT FOUND")) -> Multi-region | H13: =IF($D13="","",IFERROR(IF(INDEX(Hierarchy!$E$2:$E$1295,MATCH($D13,Hierarchy!$A$2:$A$1295,0))="","",INDEX(Hierarchy!$E$2:$E$1295,MATCH($D13,Hierarchy!$A$2:$A$1295,0))),"NODE NOT FOUND")) | I13: =IF($D13="","",IFERROR(IF(INDEX(Hierarchy!$F$2:$F$1295,MATCH($D13,Hierarchy!$A$2:$A$1295,0))="","",INDEX(Hierarchy!$F$2:$F$1295,MATCH($D13,Hierarchy!$A$2:$A$1295,0))),"NODE NOT FOUND")) | J13: =IF($D13="","",IFERROR(IF(INDEX(Hierarchy!$G$2:$G$1295,MATCH($D13,Hierarchy!$A$2:$A$1295,0))="","",INDEX(Hierarchy!$G$2:$G$1295,MATCH($D13,Hierarchy!$A$2:$A$1295,0))),"NODE NOT FOUND")) | K13: =IF($D13="","",IFERROR(IF(INDEX(Hierarchy!$H$2:$H$1295,MATCH($D13,Hierarchy!$A$2:$A$1295,0))="","",INDEX(Hierarchy!$H$2:$H$1295,MATCH($D13,Hierarchy!$A$2:$A$1295,0))),"NODE NOT FOUND")) | L13: =IF($D13="","",IFERROR(IF(INDEX(Hierarchy!$I$2:$I$1295,MATCH($D13,Hierarchy!$A$2:$A$1295,0))="","",INDEX(Hierarchy!$I$2:$I$1295,MATCH($D13,Hierarchy!$A$2:$A$1295,0))),"NODE NOT FOUND")) | M13: =IF(B13="Pre-seeded","Pre-seeded",IF(B13="Review 2026-09-16","Added from review",IF(C13="","New",IF(C13=D13,"","Changed")))) -> Changed | N13: =TRIM(SUBSTITUTE(SUBSTITUTE(SUBSTITUTE(" "&TRIM(SUBSTITUTE(SUBSTITUTE(SUBSTITUTE(SUBSTITUTE(SUBSTITUTE(SUBSTITUTE(SUBSTITUTE(SUBSTITUTE(SUBSTITUTE(SUBSTITUTE(SUBSTITUTE(SUBSTITUTE(SUBSTITUTE(SUBSTITUTE(SUBSTITUTE(UPPER(TRIM(A13)),"[MEMBER]",""),"{MEMBER}",""),"[MEMBER}",""),"MEMBER]",""),"(A)",""),"""",""),"“",""),"”",""),".",""),":",""),",",""),"–"," "),"-"," "),"/"," "),"&"," AND "))&" "," THE "," ")," TOTAL "," ")," OPERATIONS "," ")) -> AFRICA EURASIA | O13: =IF(COUNTIFS($N$2:$N$2000,N13,$D$2:$D$2000,"<>"&D13)>0,"CONFLICT","") | P13: Spans EMEA and APAC
A14: Aguascalientes | B14: Pre-seeded | D14: Aguascalientes | E14: Exact | F14: =IF($D14="","",IFERROR(IF(INDEX(Hierarchy!$B$2:$B$1295,MATCH($D14,Hierarchy!$A$2:$A$1295,0))="","",INDEX(Hierarchy!$B$2:$B$1295,MATCH($D14,Hierarchy!$A$2:$A$1295,0))),"NODE NOT FOUND")) -> State/Province | G14: =IF($D14="","",IFERROR(IF(INDEX(Hierarchy!$D$2:$D$1295,MATCH($D14,Hierarchy!$A$2:$A$1295,0))="","",INDEX(Hierarchy!$D$2:$D$1295,MATCH($D14,Hierarchy!$A$2:$A$1295,0))),"NODE NOT FOUND")) -> AMER | H14: =IF($D14="","",IFERROR(IF(INDEX(Hierarchy!$E$2:$E$1295,MATCH($D14,Hierarchy!$A$2:$A$1295,0))="","",INDEX(Hierarchy!$E$2:$E$1295,MATCH($D14,Hierarchy!$A$2:$A$1295,0))),"NODE NOT FOUND")) -> Latin America (LATAM) | I14: =IF($D14="","",IFERROR(IF(INDEX(Hierarchy!$F$2:$F$1295,MATCH($D14,Hierarchy!$A$2:$A$1295,0))="","",INDEX(Hierarchy!$F$2:$F$1295,MATCH($D14,Hierarchy!$A$2:$A$1295,0))),"NODE NOT FOUND")) -> Mexico | J14: =IF($D14="","",IFERROR(IF(INDEX(Hierarchy!$G$2:$G$1295,MATCH($D14,Hierarchy!$A$2:$A$1295,0))="","",INDEX(Hierarchy!$G$2:$G$1295,MATCH($D14,Hierarchy!$A$2:$A$1295,0))),"NODE NOT FOUND")) -> MEX | K14: =IF($D14="","",IFERROR(IF(INDEX(Hierarchy!$H$2:$H$1295,MATCH($D14,Hierarchy!$A$2:$A$1295,0))="","",INDEX(Hierarchy!$H$2:$H$1295,MATCH($D14,Hierarchy!$A$2:$A$1295,0))),"NODE NOT FOUND")) -> Aguascalientes | L14: =IF($D14="","",IFERROR(IF(INDEX(Hierarchy!$I$2:$I$1295,MATCH($D14,Hierarchy!$A$2:$A$1295,0))="","",INDEX(Hierarchy!$I$2:$I$1295,MATCH($D14,Hierarchy!$A$2:$A$1295,0))),"NODE NOT FOUND")) | M14: =IF(B14="Pre-seeded","Pre-seeded",IF(B14="Review 2026-09-16","Added from review",IF(C14="","New",IF(C14=D14,"","Changed")))) -> Pre-seeded | N14: =TRIM(SUBSTITUTE(SUBSTITUTE(SUBSTITUTE(" "&TRIM(SUBSTITUTE(SUBSTITUTE(SUBSTITUTE(SUBSTITUTE(SUBSTITUTE(SUBSTITUTE(SUBSTITUTE(SUBSTITUTE(SUBSTITUTE(SUBSTITUTE(SUBSTITUTE(SUBSTITUTE(SUBSTITUTE(SUBSTITUTE(SUBSTITUTE(UPPER(TRIM(A14)),"[MEMBER]",""),"{MEMBER}",""),"[MEMBER}",""),"MEMBER]",""),"(A)",""),"""",""),"“",""),"”",""),".",""),":",""),",",""),"–"," "),"-"," "),"/"," "),"&"," AND "))&" "," THE "," ")," TOTAL "," ")," OPERATIONS "," ")) -> AGUASCALIENTES | O14: =IF(COUNTIFS($N$2:$N$2000,N14,$D$2:$D$2000,"<>"&D14)>0,"CONFLICT","")
A15: Aichi | B15: Pre-seeded | D15: Aichi | E15: Exact | F15: =IF($D15="","",IFERROR(IF(INDEX(Hierarchy!$B$2:$B$1295,MATCH($D15,Hierarchy!$A$2:$A$1295,0))="","",INDEX(Hierarchy!$B$2:$B$1295,MATCH($D15,Hierarchy!$A$2:$A$1295,0))),"NODE NOT FOUND")) -> State/Province | G15: =IF($D15="","",IFERROR(IF(INDEX(Hierarchy!$D$2:$D$1295,MATCH($D15,Hierarchy!$A$2:$A$1295,0))="","",INDEX(Hierarchy!$D$2:$D$1295,MATCH($D15,Hierarchy!$A$2:$A$1295,0))),"NODE NOT FOUND")) -> APAC | H15: =IF($D15="","",IFERROR(IF(INDEX(Hierarchy!$E$2:$E$1295,MATCH($D15,Hierarchy!$A$2:$A$1295,0))="","",INDEX(Hierarchy!$E$2:$E$1295,MATCH($D15,Hierarchy!$A$2:$A$1295,0))),"NODE NOT FOUND")) -> East Asia | I15: =IF($D15="","",IFERROR(IF(INDEX(Hierarchy!$F$2:$F$1295,MATCH($D15,Hierarchy!$A$2:$A$1295,0))="","",INDEX(Hierarchy!$F$2:$F$1295,MATCH($D15,Hierarchy!$A$2:$A$1295,0))),"NODE NOT FOUND")) -> Japan | J15: =IF($D15="","",IFERROR(IF(INDEX(Hierarchy!$G$2:$G$1295,MATCH($D15,Hierarchy!$A$2:$A$1295,0))="","",INDEX(Hierarchy!$G$2:$G$1295,MATCH($D15,Hierarchy!$A$2:$A$1295,0))),"NODE NOT FOUND")) -> JPN | K15: =IF($D15="","",IFERROR(IF(INDEX(Hierarchy!$H$2:$H$1295,MATCH($D15,Hierarchy!$A$2:$A$1295,0))="","",INDEX(Hierarchy!$H$2:$H$1295,MATCH($D15,Hierarchy!$A$2:$A$1295,0))),"NODE NOT FOUND")) -> Aichi | L15: =IF($D15="","",IFERROR(IF(INDEX(Hierarchy!$I$2:$I$1295,MATCH($D15,Hierarchy!$A$2:$A$1295,0))="","",INDEX(Hierarchy!$I$2:$I$1295,MATCH($D15,Hierarchy!$A$2:$A$1295,0))),"NODE NOT FOUND")) | M15: =IF(B15="Pre-seeded","Pre-seeded",IF(B15="Review 2026-09-16","Added from review",IF(C15="","New",IF(C15=D15,"","Changed")))) -> Pre-seeded | N15: =TRIM(SUBSTITUTE(SUBSTITUTE(SUBSTITUTE(" "&TRIM(SUBSTITUTE(SUBSTITUTE(SUBSTITUTE(SUBSTITUTE(SUBSTITUTE(SUBSTITUTE(SUBSTITUTE(SUBSTITUTE(SUBSTITUTE(SUBSTITUTE(SUBSTITUTE(SUBSTITUTE(SUBSTITUTE(SUBSTITUTE(SUBSTITUTE(UPPER(TRIM(A15)),"[MEMBER]",""),"{MEMBER}",""),"[MEMBER}",""),"MEMBER]",""),"(A)",""),"""",""),"“",""),"”",""),".",""),":",""),",",""),"–"," "),"-"," "),"/"," "),"&"," AND "))&" "," THE "," ")," TOTAL "," ")," OPERATIONS "," ")) -> AICHI | O15: =IF(COUNTIFS($N$2:$N$2000,N15,$D$2:$D$2000,"<>"&D15)>0,"CONFLICT","")
A16: Ajman | B16: Pre-seeded | D16: Ajman | E16: Exact | F16: =IF($D16="","",IFERROR(IF(INDEX(Hierarchy!$B$2:$B$1295,MATCH($D16,Hierarchy!$A$2:$A$1295,0))="","",INDEX(Hierarchy!$B$2:$B$1295,MATCH($D16,Hierarchy!$A$2:$A$1295,0))),"NODE NOT FOUND")) -> State/Province | G16: =IF($D16="","",IFERROR(IF(INDEX(Hierarchy!$D$2:$D$1295,MATCH($D16,Hierarchy!$A$2:$A$1295,0))="","",INDEX(Hierarchy!$D$2:$D$1295,MATCH($D16,Hierarchy!$A$2:$A$1295,0))),"NODE NOT FOUND")) -> EMEA | H16: =IF($D16="","",IFERROR(IF(INDEX(Hierarchy!$E$2:$E$1295,MATCH($D16,Hierarchy!$A$2:$A$1295,0))="","",INDEX(Hierarchy!$E$2:$E$1295,MATCH($D16,Hierarchy!$A$2:$A$1295,0))),"NODE NOT FOUND")) -> Middle East | I16: =IF($D16="","",IFERROR(IF(INDEX(Hierarchy!$F$2:$F$1295,MATCH($D16,Hierarchy!$A$2:$A$1295,0))="","",INDEX(Hierarchy!$F$2:$F$1295,MATCH($D16,Hierarchy!$A$2:$A$1295,0))),"NODE NOT FOUND")) -> United Arab Emirates | J16: =IF($D16="","",IFERROR(IF(INDEX(Hierarchy!$G$2:$G$1295,MATCH($D16,Hierarchy!$A$2:$A$1295,0))="","",INDEX(Hierarchy!$G$2:$G$1295,MATCH($D16,Hierarchy!$A$2:$A$1295,0))),"NODE NOT FOUND")) -> ARE | K16: =IF($D16="","",IFERROR(IF(INDEX(Hierarchy!$H$2:$H$1295,MATCH($D16,Hierarchy!$A$2:$A$1295,0))="","",INDEX(Hierarchy!$H$2:$H$1295,MATCH($D16,Hierarchy!$A$2:$A$1295,0))),"NODE NOT FOUND")) -> Ajman | L16: =IF($D16="","",IFERROR(IF(INDEX(Hierarchy!$I$2:$I$1295,MATCH($D16,Hierarchy!$A$2:$A$1295,0))="","",INDEX(Hierarchy!$I$2:$I$1295,MATCH($D16,Hierarchy!$A$2:$A$1295,0))),"NODE NOT FOUND")) | M16: =IF(B16="Pre-seeded","Pre-seeded",IF(B16="Review 2026-09-16","Added from review",IF(C16="","New",IF(C16=D16,"","Changed")))) -> Pre-seeded | N16: =TRIM(SUBSTITUTE(SUBSTITUTE(SUBSTITUTE(" "&TRIM(SUBSTITUTE(SUBSTITUTE(SUBSTITUTE(SUBSTITUTE(SUBSTITUTE(SUBSTITUTE(SUBSTITUTE(SUBSTITUTE(SUBSTITUTE(SUBSTITUTE(SUBSTITUTE(SUBSTITUTE(SUBSTITUTE(SUBSTITUTE(SUBSTITUTE(UPPER(TRIM(A16)),"[MEMBER]",""),"{MEMBER}",""),"[MEMBER}",""),"MEMBER]",""),"(A)",""),"""",""),"“",""),"”",""),".",""),":",""),",",""),"–"," "),"-"," "),"/"," "),"&"," AND "))&" "," THE "," ")," TOTAL "," ")," OPERATIONS "," ")) -> AJMAN | O16: =IF(COUNTIFS($N$2:$N$2000,N16,$D$2:$D$2000,"<>"&D16)>0,"CONFLICT","")
A17: Akita | B17: Pre-seeded | D17: Akita | E17: Exact | F17: =IF($D17="","",IFERROR(IF(INDEX(Hierarchy!$B$2:$B$1295,MATCH($D17,Hierarchy!$A$2:$A$1295,0))="","",INDEX(Hierarchy!$B$2:$B$1295,MATCH($D17,Hierarchy!$A$2:$A$1295,0))),"NODE NOT FOUND")) -> State/Province | G17: =IF($D17="","",IFERROR(IF(INDEX(Hierarchy!$D$2:$D$1295,MATCH($D17,Hierarchy!$A$2:$A$1295,0))="","",INDEX(Hierarchy!$D$2:$D$1295,MATCH($D17,Hierarchy!$A$2:$A$1295,0))),"NODE NOT FOUND")) -> APAC | H17: =IF($D17="","",IFERROR(IF(INDEX(Hierarchy!$E$2:$E$1295,MATCH($D17,Hierarchy!$A$2:$A$1295,0))="","",INDEX(Hierarchy!$E$2:$E$1295,MATCH($D17,Hierarchy!$A$2:$A$1295,0))),"NODE NOT FOUND")) -> East Asia | I17: =IF($D17="","",IFERROR(IF(INDEX(Hierarchy!$F$2:$F$1295,MATCH($D17,Hierarchy!$A$2:$A$1295,0))="","",INDEX(Hierarchy!$F$2:$F$1295,MATCH($D17,Hierarchy!$A$2:$A$1295,0))),"NODE NOT FOUND")) -> Japan | J17: =IF($D17="","",IFERROR(IF(INDEX(Hierarchy!$G$2:$G$1295,MATCH($D17,Hierarchy!$A$2:$A$1295,0))="","",INDEX(Hierarchy!$G$2:$G$1295,MATCH($D17,Hierarchy!$A$2:$A$1295,0))),"NODE NOT FOUND")) -> JPN | K17: =IF($D17="","",IFERROR(IF(INDEX(Hierarchy!$H$2:$H$1295,MATCH($D17,Hierarchy!$A$2:$A$1295,0))="","",INDEX(Hierarchy!$H$2:$H$1295,MATCH($D17,Hierarchy!$A$2:$A$1295,0))),"NODE NOT FOUND")) -> Akita | L17: =IF($D17="","",IFERROR(IF(INDEX(Hierarchy!$I$2:$I$1295,MATCH($D17,Hierarchy!$A$2:$A$1295,0))="","",INDEX(Hierarchy!$I$2:$I$1295,MATCH($D17,Hierarchy!$A$2:$A$1295,0))),"NODE NOT FOUND")) | M17: =IF(B17="Pre-seeded","Pre-seeded",IF(B17="Review 2026-09-16","Added from review",IF(C17="","New",IF(C17=D17,"","Changed")))) -> Pre-seeded | N17: =TRIM(SUBSTITUTE(SUBSTITUTE(SUBSTITUTE(" "&TRIM(SUBSTITUTE(SUBSTITUTE(SUBSTITUTE(SUBSTITUTE(SUBSTITUTE(SUBSTITUTE(SUBSTITUTE(SUBSTITUTE(SUBSTITUTE(SUBSTITUTE(SUBSTITUTE(SUBSTITUTE(SUBSTITUTE(SUBSTITUTE(SUBSTITUTE(UPPER(TRIM(A17)),"[MEMBER]",""),"{MEMBER}",""),"[MEMBER}",""),"MEMBER]",""),"(A)",""),"""",""),"“",""),"”",""),".",""),":",""),",",""),"–"," "),"-"," "),"/"," "),"&"," AND "))&" "," THE "," ")," TOTAL "," ")," OPERATIONS "," ")) -> AKITA | O17: =IF(COUNTIFS($N$2:$N$2000,N17,$D$2:$D$2000,"<>"&D17)>0,"CONFLICT","")
A18: Akwa Ibom | B18: Pre-seeded | D18: Akwa Ibom | E18: Exact | F18: =IF($D18="","",IFERROR(IF(INDEX(Hierarchy!$B$2:$B$1295,MATCH($D18,Hierarchy!$A$2:$A$1295,0))="","",INDEX(Hierarchy!$B$2:$B$1295,MATCH($D18,Hierarchy!$A$2:$A$1295,0))),"NODE NOT FOUND")) -> State/Province | G18: =IF($D18="","",IFERROR(IF(INDEX(Hierarchy!$D$2:$D$1295,MATCH($D18,Hierarchy!$A$2:$A$1295,0))="","",INDEX(Hierarchy!$D$2:$D$1295,MATCH($D18,Hierarchy!$A$2:$A$1295,0))),"NODE NOT FOUND")) -> EMEA | H18: =IF($D18="","",IFERROR(IF(INDEX(Hierarchy!$E$2:$E$1295,MATCH($D18,Hierarchy!$A$2:$A$1295,0))="","",INDEX(Hierarchy!$E$2:$E$1295,MATCH($D18,Hierarchy!$A$2:$A$1295,0))),"NODE NOT FOUND")) -> Africa | I18: =IF($D18="","",IFERROR(IF(INDEX(Hierarchy!$F$2:$F$1295,MATCH($D18,Hierarchy!$A$2:$A$1295,0))="","",INDEX(Hierarchy!$F$2:$F$1295,MATCH($D18,Hierarchy!$A$2:$A$1295,0))),"NODE NOT FOUND")) -> Nigeria | J18: =IF($D18="","",IFERROR(IF(INDEX(Hierarchy!$G$2:$G$1295,MATCH($D18,Hierarchy!$A$2:$A$1295,0))="","",INDEX(Hierarchy!$G$2:$G$1295,MATCH($D18,Hierarchy!$A$2:$A$1295,0))),"NODE NOT FOUND")) -> NGA | K18: =IF($D18="","",IFERROR(IF(INDEX(Hierarchy!$H$2:$H$1295,MATCH($D18,Hierarchy!$A$2:$A$1295,0))="","",INDEX(Hierarchy!$H$2:$H$1295,MATCH($D18,Hierarchy!$A$2:$A$1295,0))),"NODE NOT FOUND")) -> Akwa Ibom | L18: =IF($D18="","",IFERROR(IF(INDEX(Hierarchy!$I$2:$I$1295,MATCH($D18,Hierarchy!$A$2:$A$1295,0))="","",INDEX(Hierarchy!$I$2:$I$1295,MATCH($D18,Hierarchy!$A$2:$A$1295,0))),"NODE NOT FOUND")) | M18: =IF(B18="Pre-seeded","Pre-seeded",IF(B18="Review 2026-09-16","Added from review",IF(C18="","New",IF(C18=D18,"","Changed")))) -> Pre-seeded | N18: =TRIM(SUBSTITUTE(SUBSTITUTE(SUBSTITUTE(" "&TRIM(SUBSTITUTE(SUBSTITUTE(SUBSTITUTE(SUBSTITUTE(SUBSTITUTE(SUBSTITUTE(SUBSTITUTE(SUBSTITUTE(SUBSTITUTE(SUBSTITUTE(SUBSTITUTE(SUBSTITUTE(SUBSTITUTE(SUBSTITUTE(SUBSTITUTE(UPPER(TRIM(A18)),"[MEMBER]",""),"{MEMBER}",""),"[MEMBER}",""),"MEMBER]",""),"(A)",""),"""",""),"“",""),"”",""),".",""),":",""),",",""),"–"," "),"-"," "),"/"," "),"&"," AND "))&" "," THE "," ")," TOTAL "," ")," OPERATIONS "," ")) -> AKWA IBOM | O18: =IF(COUNTIFS($N$2:$N$2000,N18,$D$2:$D$2000,"<>"&D18)>0,"CONFLICT","")
A19: Al Bahah Province | B19: Pre-seeded | D19: Al Bahah Province | E19: Exact | F19: =IF($D19="","",IFERROR(IF(INDEX(Hierarchy!$B$2:$B$1295,MATCH($D19,Hierarchy!$A$2:$A$1295,0))="","",INDEX(Hierarchy!$B$2:$B$1295,MATCH($D19,Hierarchy!$A$2:$A$1295,0))),"NODE NOT FOUND")) -> State/Province | G19: =IF($D19="","",IFERROR(IF(INDEX(Hierarchy!$D$2:$D$1295,MATCH($D19,Hierarchy!$A$2:$A$1295,0))="","",INDEX(Hierarchy!$D$2:$D$1295,MATCH($D19,Hierarchy!$A$2:$A$1295,0))),"NODE NOT FOUND")) -> EMEA | H19: =IF($D19="","",IFERROR(IF(INDEX(Hierarchy!$E$2:$E$1295,MATCH($D19,Hierarchy!$A$2:$A$1295,0))="","",INDEX(Hierarchy!$E$2:$E$1295,MATCH($D19,Hierarchy!$A$2:$A$1295,0))),"NODE NOT FOUND")) -> Middle East | I19: =IF($D19="","",IFERROR(IF(INDEX(Hierarchy!$F$2:$F$1295,MATCH($D19,Hierarchy!$A$2:$A$1295,0))="","",INDEX(Hierarchy!$F$2:$F$1295,MATCH($D19,Hierarchy!$A$2:$A$1295,0))),"NODE NOT FOUND")) -> Saudi Arabia | J19: =IF($D19="","",IFERROR(IF(INDEX(Hierarchy!$G$2:$G$1295,MATCH($D19,Hierarchy!$A$2:$A$1295,0))="","",INDEX(Hierarchy!$G$2:$G$1295,MATCH($D19,Hierarchy!$A$2:$A$1295,0))),"NODE NOT FOUND")) -> SAU | K19: =IF($D19="","",IFERROR(IF(INDEX(Hierarchy!$H$2:$H$1295,MATCH($D19,Hierarchy!$A$2:$A$1295,0))="","",INDEX(Hierarchy!$H$2:$H$1295,MATCH($D19,Hierarchy!$A$2:$A$1295,0))),"NODE NOT FOUND")) -> Al Bahah Province | L19: =IF($D19="","",IFERROR(IF(INDEX(Hierarchy!$I$2:$I$1295,MATCH($D19,Hierarchy!$A$2:$A$1295,0))="","",INDEX(Hierarchy!$I$2:$I$1295,MATCH($D19,Hierarchy!$A$2:$A$1295,0))),"NODE NOT FOUND")) | M19: =IF(B19="Pre-seeded","Pre-seeded",IF(B19="Review 2026-09-16","Added from review",IF(C19="","New",IF(C19=D19,"","Changed")))) -> Pre-seeded | N19: =TRIM(SUBSTITUTE(SUBSTITUTE(SUBSTITUTE(" "&TRIM(SUBSTITUTE(SUBSTITUTE(SUBSTITUTE(SUBSTITUTE(SUBSTITUTE(SUBSTITUTE(SUBSTITUTE(SUBSTITUTE(SUBSTITUTE(SUBSTITUTE(SUBSTITUTE(SUBSTITUTE(SUBSTITUTE(SUBSTITUTE(SUBSTITUTE(UPPER(TRIM(A19)),"[MEMBER]",""),"{MEMBER}",""),"[MEMBER}",""),"MEMBER]",""),"(A)",""),"""",""),"“",""),"”",""),".",""),":",""),",",""),"–"," "),"-"," "),"/"," "),"&"," AND "))&" "," THE "," ")," TOTAL "," ")," OPERATIONS "," ")) -> AL BAHAH PROVINCE | O19: =IF(COUNTIFS($N$2:$N$2000,N19,$D$2:$D$2000,"<>"&D19)>0,"CONFLICT","")
A20: Al Jawf Province | B20: Pre-seeded | D20: Al Jawf Province | E20: Exact | F20: =IF($D20="","",IFERROR(IF(INDEX(Hierarchy!$B$2:$B$1295,MATCH($D20,Hierarchy!$A$2:$A$1295,0))="","",INDEX(Hierarchy!$B$2:$B$1295,MATCH($D20,Hierarchy!$A$2:$A$1295,0))),"NODE NOT FOUND")) -> State/Province | G20: =IF($D20="","",IFERROR(IF(INDEX(Hierarchy!$D$2:$D$1295,MATCH($D20,Hierarchy!$A$2:$A$1295,0))="","",INDEX(Hierarchy!$D$2:$D$1295,MATCH($D20,Hierarchy!$A$2:$A$1295,0))),"NODE NOT FOUND")) -> EMEA | H20: =IF($D20="","",IFERROR(IF(INDEX(Hierarchy!$E$2:$E$1295,MATCH($D20,Hierarchy!$A$2:$A$1295,0))="","",INDEX(Hierarchy!$E$2:$E$1295,MATCH($D20,Hierarchy!$A$2:$A$1295,0))),"NODE NOT FOUND")) -> Middle East | I20: =IF($D20="","",IFERROR(IF(INDEX(Hierarchy!$F$2:$F$1295,MATCH($D20,Hierarchy!$A$2:$A$1295,0))="","",INDEX(Hierarchy!$F$2:$F$1295,MATCH($D20,Hierarchy!$A$2:$A$1295,0))),"NODE NOT FOUND")) -> Saudi Arabia | J20: =IF($D20="","",IFERROR(IF(INDEX(Hierarchy!$G$2:$G$1295,MATCH($D20,Hierarchy!$A$2:$A$1295,0))="","",INDEX(Hierarchy!$G$2:$G$1295,MATCH($D20,Hierarchy!$A$2:$A$1295,0))),"NODE NOT FOUND")) -> SAU | K20: =IF($D20="","",IFERROR(IF(INDEX(Hierarchy!$H$2:$H$1295,MATCH($D20,Hierarchy!$A$2:$A$1295,0))="","",INDEX(Hierarchy!$H$2:$H$1295,MATCH($D20,Hierarchy!$A$2:$A$1295,0))),"NODE NOT FOUND")) -> Al Jawf Province | L20: =IF($D20="","",IFERROR(IF(INDEX(Hierarchy!$I$2:$I$1295,MATCH($D20,Hierarchy!$A$2:$A$1295,0))="","",INDEX(Hierarchy!$I$2:$I$1295,MATCH($D20,Hierarchy!$A$2:$A$1295,0))),"NODE NOT FOUND")) | M20: =IF(B20="Pre-seeded","Pre-seeded",IF(B20="Review 2026-09-16","Added from review",IF(C20="","New",IF(C20=D20,"","Changed")))) -> Pre-seeded | N20: =TRIM(SUBSTITUTE(SUBSTITUTE(SUBSTITUTE(" "&TRIM(SUBSTITUTE(SUBSTITUTE(SUBSTITUTE(SUBSTITUTE(SUBSTITUTE(SUBSTITUTE(SUBSTITUTE(SUBSTITUTE(SUBSTITUTE(SUBSTITUTE(SUBSTITUTE(SUBSTITUTE(SUBSTITUTE(SUBSTITUTE(SUBSTITUTE(UPPER(TRIM(A20)),"[MEMBER]",""),"{MEMBER}",""),"[MEMBER}",""),"MEMBER]",""),"(A)",""),"""",""),"“",""),"”",""),".",""),":",""),",",""),"–"," "),"-"," "),"/"," "),"&"," AND "))&" "," THE "," ")," TOTAL "," ")," OPERATIONS "," ")) -> AL JAWF PROVINCE | O20: =IF(COUNTIFS($N$2:$N$2000,N20,$D$2:$D$2000,"<>"&D20)>0,"CONFLICT","")
A21: ALABAMA | B21: Mapping | C21: Alabama | D21: Alabama | E21: Exact | F21: =IF($D21="","",IFERROR(IF(INDEX(Hierarchy!$B$2:$B$1295,MATCH($D21,Hierarchy!$A$2:$A$1295,0))="","",INDEX(Hierarchy!$B$2:$B$1295,MATCH($D21,Hierarchy!$A$2:$A$1295,0))),"NODE NOT FOUND")) -> State/Province | G21: =IF($D21="","",IFERROR(IF(INDEX(Hierarchy!$D$2:$D$1295,MATCH($D21,Hierarchy!$A$2:$A$1295,0))="","",INDEX(Hierarchy!$D$2:$D$1295,MATCH($D21,Hierarchy!$A$2:$A$1295,0))),"NODE NOT FOUND")) -> AMER | H21: =IF($D21="","",IFERROR(IF(INDEX(Hierarchy!$E$2:$E$1295,MATCH($D21,Hierarchy!$A$2:$A$1295,0))="","",INDEX(Hierarchy!$E$2:$E$1295,MATCH($D21,Hierarchy!$A$2:$A$1295,0))),"NODE NOT FOUND")) -> North America (NORAM) | I21: =IF($D21="","",IFERROR(IF(INDEX(Hierarchy!$F$2:$F$1295,MATCH($D21,Hierarchy!$A$2:$A$1295,0))="","",INDEX(Hierarchy!$F$2:$F$1295,MATCH($D21,Hierarchy!$A$2:$A$1295,0))),"NODE NOT FOUND")) -> United States | J21: =IF($D21="","",IFERROR(IF(INDEX(Hierarchy!$G$2:$G$1295,MATCH($D21,Hierarchy!$A$2:$A$1295,0))="","",INDEX(Hierarchy!$G$2:$G$1295,MATCH($D21,Hierarchy!$A$2:$A$1295,0))),"NODE NOT FOUND")) -> USA | K21: =IF($D21="","",IFERROR(IF(INDEX(Hierarchy!$H$2:$H$1295,MATCH($D21,Hierarchy!$A$2:$A$1295,0))="","",INDEX(Hierarchy!$H$2:$H$1295,MATCH($D21,Hierarchy!$A$2:$A$1295,0))),"NODE NOT FOUND")) -> Alabama | L21: =IF($D21="","",IFERROR(IF(INDEX(Hierarchy!$I$2:$I$1295,MATCH($D21,Hierarchy!$A$2:$A$1295,0))="","",INDEX(Hierarchy!$I$2:$I$1295,MATCH($D21,Hierarchy!$A$2:$A$1295,0))),"NODE NOT FOUND")) | M21: =IF(B21="Pre-seeded","Pre-seeded",IF(B21="Review 2026-09-16","Added from review",IF(C21="","New",IF(C21=D21,"","Changed")))) | N21: =TRIM(SUBSTITUTE(SUBSTITUTE(SUBSTITUTE(" "&TRIM(SUBSTITUTE(SUBSTITUTE(SUBSTITUTE(SUBSTITUTE(SUBSTITUTE(SUBSTITUTE(SUBSTITUTE(SUBSTITUTE(SUBSTITUTE(SUBSTITUTE(SUBSTITUTE(SUBSTITUTE(SUBSTITUTE(SUBSTITUTE(SUBSTITUTE(UPPER(TRIM(A21)),"[MEMBER]",""),"{MEMBER}",""),"[MEMBER}",""),"MEMBER]",""),"(A)",""),"""",""),"“",""),"”",""),".",""),":",""),",",""),"–"," "),"-"," "),"/"," "),"&"," AND "))&" "," THE "," ")," TOTAL "," ")," OPERATIONS "," ")) -> ALABAMA | O21: =IF(COUNTIFS($N$2:$N$2000,N21,$D$2:$D$2000,"<>"&D21)>0,"CONFLICT","")
